Workbook

Sheet 112417 - 2 (2)
A1: Date | B1: 07.07.2022
A2: Sale Case | B2: 112417
A3: Cilent | B3: Metron
A6: Panel Size | B6: H | C6: W | D6: D | G6: Bus Bar | H6: Qty(Feet) | I6: Weight | J6: Saleeve Cost
B7: 1300 | C7: 1050 | D7: 450 | G7: 30x5 | H7: 10.5 | I7: =IF(G7="20x5",H7*0.3)+IF(G7="25x5",H7*0.4)+IF(G7="25x10",H7*0.7)+IF(G7="30x5",H7*0.45)+IF(G7="30x10",H7*0.85)+IF(G7="40x5",H7*0.6)+IF(G7="40x10",H7*1.1)+IF(G7="50x5",H7*0.7)+IF(G7="50x10",H7*1.4)+IF(G7="60x5",H7*0.85)+IF(G7="60x10",H7*1.7)+IF(G7="80x5",H7*1.1)+IF(G7="80x10",H7*2.2)+IF(G7="100x5",H7*1.4)+IF(G7="100x10",H7*2.8)+IF(G7="120x5",H7*1.67)+IF(G7="120x10",H7*3.3)+IF(G7="150x10",H7*4.2) -> 4.725 | J7: =IF(G7="20x5",H7*43*1.5)+IF(G7="25x5",H7*48*1.5)+IF(G7="25x10",H7*55*1.5)+IF(G7="30x5",H7*60*1.5)+IF(G7="30x10",H7*65*1.5)+IF(G7="40x5",H7*65*1.5)+IF(G7="40x10",H7*75*1.5)+IF(G7="50x5",H7*75*1.5)+IF(G7="50x10",H7*85*1.5)+IF(G7="60x5",H7*85*1.5)+IF(G7="60x10",H7*95*1.5)+IF(G7="80x5",H7*110*1.5)+IF(G7="80x10",H7*115*1.5)+IF(G7="100x5",H7*125*1.5)+IF(G7="100x10",H7*135*1.5)+IF(G7="120x5",H7*145*1.5)+IF(G7="120x10",H7*155*1.5)+IF(G7="150x10",H7*185*1.5) -> 945
A8: Sheet Use | B8: 3.75 | G8: 25x5 | H8: 15.5 | I8: =IF(G8="20x5",H8*0.3)+IF(G8="25x5",H8*0.4)+IF(G8="25x10",H8*0.7)+IF(G8="30x5",H8*0.45)+IF(G8="30x10",H8*0.85)+IF(G8="40x5",H8*0.6)+IF(G8="40x10",H8*1.1)+IF(G8="50x5",H8*0.7)+IF(G8="50x10",H8*1.4)+IF(G8="60x5",H8*0.85)+IF(G8="60x10",H8*1.7)+IF(G8="80x5",H8*1.1)+IF(G8="80x10",H8*2.2)+IF(G8="100x5",H8*1.4)+IF(G8="100x10",H8*2.8)+IF(G8="120x5",H8*1.67)+IF(G8="120x10",H8*3.3)+IF(G8="150x10",H8*4.2) -> 6.2 | J8: =IF(G8="20x5",H8*43*1.5)+IF(G8="25x5",H8*48*1.5)+IF(G8="25x10",H8*55*1.5)+IF(G8="30x5",H8*60*1.5)+IF(G8="30x10",H8*65*1.5)+IF(G8="40x5",H8*65*1.5)+IF(G8="40x10",H8*75*1.5)+IF(G8="50x5",H8*75*1.5)+IF(G8="50x10",H8*85*1.5)+IF(G8="60x5",H8*85*1.5)+IF(G8="60x10",H8*95*1.5)+IF(G8="80x5",H8*110*1.5)+IF(G8="80x10",H8*115*1.5)+IF(G8="100x5",H8*125*1.5)+IF(G8="100x10",H8*135*1.5)+IF(G8="120x5",H8*145*1.5)+IF(G8="120x10",H8*155*1.5)+IF(G8="150x10",H8*185*1.5) -> 1116
A9: Sheet Selection | B9: MS Sheet | G9: 20x5 | H9: 3.5 | I9: =IF(G9="20x5",H9*0.3)+IF(G9="25x5",H9*0.4)+IF(G9="25x10",H9*0.7)+IF(G9="30x5",H9*0.45)+IF(G9="30x10",H9*0.85)+IF(G9="40x5",H9*0.6)+IF(G9="40x10",H9*1.1)+IF(G9="50x5",H9*0.7)+IF(G9="50x10",H9*1.4)+IF(G9="60x5",H9*0.85)+IF(G9="60x10",H9*1.7)+IF(G9="80x5",H9*1.1)+IF(G9="80x10",H9*2.2)+IF(G9="100x5",H9*1.4)+IF(G9="100x10",H9*2.8)+IF(G9="120x5",H9*1.67)+IF(G9="120x10",H9*3.3)+IF(G9="150x10",H9*4.2) -> 1.05 | J9: =IF(G9="20x5",H9*43*1.5)+IF(G9="25x5",H9*48*1.5)+IF(G9="25x10",H9*55*1.5)+IF(G9="30x5",H9*60*1.5)+IF(G9="30x10",H9*65*1.5)+IF(G9="40x5",H9*65*1.5)+IF(G9="40x10",H9*75*1.5)+IF(G9="50x5",H9*75*1.5)+IF(G9="50x10",H9*85*1.5)+IF(G9="60x5",H9*85*1.5)+IF(G9="60x10",H9*95*1.5)+IF(G9="80x5",H9*110*1.5)+IF(G9="80x10",H9*115*1.5)+IF(G9="100x5",H9*125*1.5)+IF(G9="100x10",H9*135*1.5)+IF(G9="120x5",H9*145*1.5)+IF(G9="120x10",H9*155*1.5)+IF(G9="150x10",H9*185*1.5) -> 225.75
A10: Sheet SWG | B10: 14SWG | C10: 16SWG | D10: 18SWG | I10: =IF(G10="20x5",H10*0.3)+IF(G10="25x5",H10*0.4)+IF(G10="25x10",H10*0.7)+IF(G10="30x5",H10*0.45)+IF(G10="30x10",H10*0.85)+IF(G10="40x5",H10*0.6)+IF(G10="40x10",H10*1.1)+IF(G10="50x5",H10*0.7)+IF(G10="50x10",H10*1.4)+IF(G10="60x5",H10*0.85)+IF(G10="60x10",H10*1.7)+IF(G10="80x5",H10*1.1)+IF(G10="80x10",H10*2.2)+IF(G10="100x5",H10*1.4)+IF(G10="100x10",H10*2.8)+IF(G10="120x5",H10*1.67)+IF(G10="120x10",H10*3.3)+IF(G10="150x10",H10*4.2) -> 0 | J10: =IF(G10="20x5",H10*43*1.5)+IF(G10="25x5",H10*48*1.5)+IF(G10="25x10",H10*55*1.5)+IF(G10="30x5",H10*60*1.5)+IF(G10="30x10",H10*65*1.5)+IF(G10="40x5",H10*65*1.5)+IF(G10="40x10",H10*75*1.5)+IF(G10="50x5",H10*75*1.5)+IF(G10="50x10",H10*85*1.5)+IF(G10="60x5",H10*85*1.5)+IF(G10="60x10",H10*95*1.5)+IF(G10="80x5",H10*110*1.5)+IF(G10="80x10",H10*115*1.5)+IF(G10="100x5",H10*125*1.5)+IF(G10="100x10",H10*135*1.5)+IF(G10="120x5",H10*145*1.5)+IF(G10="120x10",H10*155*1.5)+IF(G10="150x10",H10*185*1.5) -> 0
A11: Sheet Weight | B11: =B8*48.64 -> 182.4 | C11: =B8*38.4 -> 144 | D11: =B8*28 -> 105 | I11: =IF(G11="20x5",H11*0.3)+IF(G11="25x5",H11*0.4)+IF(G11="25x10",H11*0.7)+IF(G11="30x5",H11*0.45)+IF(G11="30x10",H11*0.85)+IF(G11="40x5",H11*0.6)+IF(G11="40x10",H11*1.1)+IF(G11="50x5",H11*0.7)+IF(G11="50x10",H11*1.4)+IF(G11="60x5",H11*0.85)+IF(G11="60x10",H11*1.7)+IF(G11="80x5",H11*1.1)+IF(G11="80x10",H11*2.2)+IF(G11="100x5",H11*1.4)+IF(G11="100x10",H11*2.8)+IF(G11="120x5",H11*1.67)+IF(G11="120x10",H11*3.3)+IF(G11="150x10",H11*4.2) -> 0 | J11: =IF(G11="20x5",H11*43*1.5)+IF(G11="25x5",H11*48*1.5)+IF(G11="25x10",H11*55*1.5)+IF(G11="30x5",H11*60*1.5)+IF(G11="30x10",H11*65*1.5)+IF(G11="40x5",H11*65*1.5)+IF(G11="40x10",H11*75*1.5)+IF(G11="50x5",H11*75*1.5)+IF(G11="50x10",H11*85*1.5)+IF(G11="60x5",H11*85*1.5)+IF(G11="60x10",H11*95*1.5)+IF(G11="80x5",H11*110*1.5)+IF(G11="80x10",H11*115*1.5)+IF(G11="100x5",H11*125*1.5)+IF(G11="100x10",H11*135*1.5)+IF(G11="120x5",H11*145*1.5)+IF(G11="120x10",H11*155*1.5)+IF(G11="150x10",H11*185*1.5) -> 0
A12: Sheet Cost | B12: =IF(B9="MS Sheet",B11*'Cost-Sheet'!B7)+IF(B9="SS Sheet",B11*'Cost-Sheet'!C7)+IF(B9="GI Sheet",B11*'Cost-Sheet'!D7) -> 52896 | C12: =IF(B9="MS Sheet",C11*'Cost-Sheet'!B7)+IF(B9="SS Sheet",C11*'Cost-Sheet'!C7)+IF(B9="GI Sheet",C11*'Cost-Sheet'!D7) -> 41760 | D12: =IF(B9="MS Sheet",D11*'Cost-Sheet'!B7)+IF(B9="SS Sheet",D11*'Cost-Sheet'!C7)+IF(B9="GI Sheet",D11*'Cost-Sheet'!D7) -> 30450 | I12: =IF(G12="20x5",H12*0.3)+IF(G12="25x5",H12*0.4)+IF(G12="25x10",H12*0.7)+IF(G12="30x5",H12*0.45)+IF(G12="30x10",H12*0.85)+IF(G12="40x5",H12*0.6)+IF(G12="40x10",H12*1.1)+IF(G12="50x5",H12*0.7)+IF(G12="50x10",H12*1.4)+IF(G12="60x5",H12*0.85)+IF(G12="60x10",H12*1.7)+IF(G12="80x5",H12*1.1)+IF(G12="80x10",H12*2.2)+IF(G12="100x5",H12*1.4)+IF(G12="100x10",H12*2.8)+IF(G12="120x5",H12*1.67)+IF(G12="120x10",H12*3.3)+IF(G12="150x10",H12*4.2) -> 0 | J12: =IF(G12="20x5",H12*43*1.5)+IF(G12="25x5",H12*48*1.5)+IF(G12="25x10",H12*55*1.5)+IF(G12="30x5",H12*60*1.5)+IF(G12="30x10",H12*65*1.5)+IF(G12="40x5",H12*65*1.5)+IF(G12="40x10",H12*75*1.5)+IF(G12="50x5",H12*75*1.5)+IF(G12="50x10",H12*85*1.5)+IF(G12="60x5",H12*85*1.5)+IF(G12="60x10",H12*95*1.5)+IF(G12="80x5",H12*110*1.5)+IF(G12="80x10",H12*115*1.5)+IF(G12="100x5",H12*125*1.5)+IF(G12="100x10",H12*135*1.5)+IF(G12="120x5",H12*145*1.5)+IF(G12="120x10",H12*155*1.5)+IF(G12="150x10",H12*185*1.5) -> 0
I13: =IF(G13="20x5",H13*0.3)+IF(G13="25x5",H13*0.4)+IF(G13="25x10",H13*0.7)+IF(G13="30x5",H13*0.45)+IF(G13="30x10",H13*0.85)+IF(G13="40x5",H13*0.6)+IF(G13="40x10",H13*1.1)+IF(G13="50x5",H13*0.7)+IF(G13="50x10",H13*1.4)+IF(G13="60x5",H13*0.85)+IF(G13="60x10",H13*1.7)+IF(G13="80x5",H13*1.1)+IF(G13="80x10",H13*2.2)+IF(G13="100x5",H13*1.4)+IF(G13="100x10",H13*2.8)+IF(G13="120x5",H13*1.67)+IF(G13="120x10",H13*3.3)+IF(G13="150x10",H13*4.2) -> 0 | J13: =IF(G13="20x5",H13*43*1.5)+IF(G13="25x5",H13*48*1.5)+IF(G13="25x10",H13*55*1.5)+IF(G13="30x5",H13*60*1.5)+IF(G13="30x10",H13*65*1.5)+IF(G13="40x5",H13*65*1.5)+IF(G13="40x10",H13*75*1.5)+IF(G13="50x5",H13*75*1.5)+IF(G13="50x10",H13*85*1.5)+IF(G13="60x5",H13*85*1.5)+IF(G13="60x10",H13*95*1.5)+IF(G13="80x5",H13*110*1.5)+IF(G13="80x10",H13*115*1.5)+IF(G13="100x5",H13*125*1.5)+IF(G13="100x10",H13*135*1.5)+IF(G13="120x5",H13*145*1.5)+IF(G13="120x10",H13*155*1.5)+IF(G13="150x10",H13*185*1.5) -> 0
A14: Paint Cost | I14: =IF(G14="20x5",H14*0.3)+IF(G14="25x5",H14*0.4)+IF(G14="25x10",H14*0.7)+IF(G14="30x5",H14*0.45)+IF(G14="30x10",H14*0.85)+IF(G14="40x5",H14*0.6)+IF(G14="40x10",H14*1.1)+IF(G14="50x5",H14*0.7)+IF(G14="50x10",H14*1.4)+IF(G14="60x5",H14*0.85)+IF(G14="60x10",H14*1.7)+IF(G14="80x5",H14*1.1)+IF(G14="80x10",H14*2.2)+IF(G14="100x5",H14*1.4)+IF(G14="100x10",H14*2.8)+IF(G14="120x5",H14*1.67)+IF(G14="120x10",H14*3.3)+IF(G14="150x10",H14*4.2) -> 0 | J14: =IF(G14="20x5",H14*43*1.5)+IF(G14="25x5",H14*48*1.5)+IF(G14="25x10",H14*55*1.5)+IF(G14="30x5",H14*60*1.5)+IF(G14="30x10",H14*65*1.5)+IF(G14="40x5",H14*65*1.5)+IF(G14="40x10",H14*75*1.5)+IF(G14="50x5",H14*75*1.5)+IF(G14="50x10",H14*85*1.5)+IF(G14="60x5",H14*85*1.5)+IF(G14="60x10",H14*95*1.5)+IF(G14="80x5",H14*110*1.5)+IF(G14="80x10",H14*115*1.5)+IF(G14="100x5",H14*125*1.5)+IF(G14="100x10",H14*135*1.5)+IF(G14="120x5",H14*145*1.5)+IF(G14="120x10",H14*155*1.5)+IF(G14="150x10",H14*185*1.5) -> 0
A15: 7035 | B15: =IF(AND(OR(D7=100,D7=125,D7=130,D7=150,D7=160,D7=200),A15=7035),'Cost-Sheet'!I8*B7*C7/645.16/144)+IF(AND(OR(D7=250,D7=300),A15=7035),'Cost-Sheet'!I9*B7*C7/645.16/144)+IF(AND(OR(D7=350,D7=380,D7=400,D7=450),A15=7035),'Cost-Sheet'!I10*B7*C7/645.16/144)+IF(AND(OR(D7=500,D7=600),A15=7035),'Cost-Sheet'!I11*B7*C7/645.16/144)+IF(AND(OR(D7=700,D7=750,D7=800),A15=7035),'Cost-Sheet'!I12*B7*C7/645.16/144)+IF(AND(OR(D7=900,D7=1000,D7=1100,D7=1200),A15=7035),'Cost-Sheet'!I13*B7*C7/645.16/144)+IF(AND(OR(D7=100,D7=125,D7=130,D7=150,D7=160,D7=200),A15=7032),'Cost-Sheet'!H8*B7*C7/645.16/144)+IF(AND(OR(D7=250,D7=300),A15=7032),'Cost-Sheet'!H9*B7*C7/645.16/144)+IF(AND(OR(D7=350,D7=380,D7=400,D7=450),A15=7032),'Cost-Sheet'!H10*B7*C7/645.16/144)+IF(AND(OR(D7=500,D7=600),A15=7032),'Cost-Sheet'!H11*B7*C7/645.16/144)+IF(AND(OR(D7=700,D7=750,D7=800),A15=7032),'Cost-Sheet'!H12*B7*C7/645.16/144)+IF(AND(OR(D7=900,D7=1000,D7=1100,D7=1200),A15=7032),'Cost-Sheet'!H13*B7*C7/645.16/144) -> 8264.665 | I15: =IF(G15="20x5",H15*0.3)+IF(G15="25x5",H15*0.4)+IF(G15="25x10",H15*0.7)+IF(G15="30x5",H15*0.45)+IF(G15="30x10",H15*0.85)+IF(G15="40x5",H15*0.6)+IF(G15="40x10",H15*1.1)+IF(G15="50x5",H15*0.7)+IF(G15="50x10",H15*1.4)+IF(G15="60x5",H15*0.85)+IF(G15="60x10",H15*1.7)+IF(G15="80x5",H15*1.1)+IF(G15="80x10",H15*2.2)+IF(G15="100x5",H15*1.4)+IF(G15="100x10",H15*2.8)+IF(G15="120x5",H15*1.67)+IF(G15="120x10",H15*3.3)+IF(G15="150x10",H15*4.2) -> 0 | J15: =IF(G15="20x5",H15*43*1.5)+IF(G15="25x5",H15*48*1.5)+IF(G15="25x10",H15*55*1.5)+IF(G15="30x5",H15*60*1.5)+IF(G15="30x10",H15*65*1.5)+IF(G15="40x5",H15*65*1.5)+IF(G15="40x10",H15*75*1.5)+IF(G15="50x5",H15*75*1.5)+IF(G15="50x10",H15*85*1.5)+IF(G15="60x5",H15*85*1.5)+IF(G15="60x10",H15*95*1.5)+IF(G15="80x5",H15*110*1.5)+IF(G15="80x10",H15*115*1.5)+IF(G15="100x5",H15*125*1.5)+IF(G15="100x10",H15*135*1.5)+IF(G15="120x5",H15*145*1.5)+IF(G15="120x10",H15*155*1.5)+IF(G15="150x10",H15*185*1.5) -> 0
I16: =IF(G16="20x5",H16*0.3)+IF(G16="25x5",H16*0.4)+IF(G16="25x10",H16*0.7)+IF(G16="30x5",H16*0.45)+IF(G16="30x10",H16*0.85)+IF(G16="40x5",H16*0.6)+IF(G16="40x10",H16*1.1)+IF(G16="50x5",H16*0.7)+IF(G16="50x10",H16*1.4)+IF(G16="60x5",H16*0.85)+IF(G16="60x10",H16*1.7)+IF(G16="80x5",H16*1.1)+IF(G16="80x10",H16*2.2)+IF(G16="100x5",H16*1.4)+IF(G16="100x10",H16*2.8)+IF(G16="120x5",H16*1.67)+IF(G16="120x10",H16*3.3)+IF(G16="150x10",H16*4.2) -> 0 | J16: =IF(G16="20x5",H16*43*1.5)+IF(G16="25x5",H16*48*1.5)+IF(G16="25x10",H16*55*1.5)+IF(G16="30x5",H16*60*1.5)+IF(G16="30x10",H16*65*1.5)+IF(G16="40x5",H16*65*1.5)+IF(G16="40x10",H16*75*1.5)+IF(G16="50x5",H16*75*1.5)+IF(G16="50x10",H16*85*1.5)+IF(G16="60x5",H16*85*1.5)+IF(G16="60x10",H16*95*1.5)+IF(G16="80x5",H16*110*1.5)+IF(G16="80x10",H16*115*1.5)+IF(G16="100x5",H16*125*1.5)+IF(G16="100x10",H16*135*1.5)+IF(G16="120x5",H16*145*1.5)+IF(G16="120x10",H16*155*1.5)+IF(G16="150x10",H16*185*1.5) -> 0
A17: Rent | B17: 2000 | I17: =IF(G17="20x5",H17*0.3)+IF(G17="25x5",H17*0.4)+IF(G17="25x10",H17*0.7)+IF(G17="30x5",H17*0.45)+IF(G17="30x10",H17*0.85)+IF(G17="40x5",H17*0.6)+IF(G17="40x10",H17*1.1)+IF(G17="50x5",H17*0.7)+IF(G17="50x10",H17*1.4)+IF(G17="60x5",H17*0.85)+IF(G17="60x10",H17*1.7)+IF(G17="80x5",H17*1.1)+IF(G17="80x10",H17*2.2)+IF(G17="100x5",H17*1.4)+IF(G17="100x10",H17*2.8)+IF(G17="120x5",H17*1.67)+IF(G17="120x10",H17*3.3)+IF(G17="150x10",H17*4.2) -> 0 | J17: =IF(G17="20x5",H17*43*1.5)+IF(G17="25x5",H17*48*1.5)+IF(G17="25x10",H17*55*1.5)+IF(G17="30x5",H17*60*1.5)+IF(G17="30x10",H17*65*1.5)+IF(G17="40x5",H17*65*1.5)+IF(G17="40x10",H17*75*1.5)+IF(G17="50x5",H17*75*1.5)+IF(G17="50x10",H17*85*1.5)+IF(G17="60x5",H17*85*1.5)+IF(G17="60x10",H17*95*1.5)+IF(G17="80x5",H17*110*1.5)+IF(G17="80x10",H17*115*1.5)+IF(G17="100x5",H17*125*1.5)+IF(G17="100x10",H17*135*1.5)+IF(G17="120x5",H17*145*1.5)+IF(G17="120x10",H17*155*1.5)+IF(G17="150x10",H17*185*1.5) -> 0
I18: =IF(G18="20x5",H18*0.3)+IF(G18="25x5",H18*0.4)+IF(G18="25x10",H18*0.7)+IF(G18="30x5",H18*0.45)+IF(G18="30x10",H18*0.85)+IF(G18="40x5",H18*0.6)+IF(G18="40x10",H18*1.1)+IF(G18="50x5",H18*0.7)+IF(G18="50x10",H18*1.4)+IF(G18="60x5",H18*0.85)+IF(G18="60x10",H18*1.7)+IF(G18="80x5",H18*1.1)+IF(G18="80x10",H18*2.2)+IF(G18="100x5",H18*1.4)+IF(G18="100x10",H18*2.8)+IF(G18="120x5",H18*1.67)+IF(G18="120x10",H18*3.3)+IF(G18="150x10",H18*4.2) -> 0 | J18: =IF(G18="20x5",H18*43*1.5)+IF(G18="25x5",H18*48*1.5)+IF(G18="25x10",H18*55*1.5)+IF(G18="30x5",H18*60*1.5)+IF(G18="30x10",H18*65*1.5)+IF(G18="40x5",H18*65*1.5)+IF(G18="40x10",H18*75*1.5)+IF(G18="50x5",H18*75*1.5)+IF(G18="50x10",H18*85*1.5)+IF(G18="60x5",H18*85*1.5)+IF(G18="60x10",H18*95*1.5)+IF(G18="80x5",H18*110*1.5)+IF(G18="80x10",H18*115*1.5)+IF(G18="100x5",H18*125*1.5)+IF(G18="100x10",H18*135*1.5)+IF(G18="120x5",H18*145*1.5)+IF(G18="120x10",H18*155*1.5)+IF(G18="150x10",H18*185*1.5) -> 0
A19: HINGES | B19: Model | C19: Qty | D19: Cost | I19: =IF(G19="20x5",H19*0.3)+IF(G19="25x5",H19*0.4)+IF(G19="25x10",H19*0.7)+IF(G19="30x5",H19*0.45)+IF(G19="30x10",H19*0.85)+IF(G19="40x5",H19*0.6)+IF(G19="40x10",H19*1.1)+IF(G19="50x5",H19*0.7)+IF(G19="50x10",H19*1.4)+IF(G19="60x5",H19*0.85)+IF(G19="60x10",H19*1.7)+IF(G19="80x5",H19*1.1)+IF(G19="80x10",H19*2.2)+IF(G19="100x5",H19*1.4)+IF(G19="100x10",H19*2.8)+IF(G19="120x5",H19*1.67)+IF(G19="120x10",H19*3.3)+IF(G19="150x10",H19*4.2) -> 0 | J19: =IF(G19="20x5",H19*43*1.5)+IF(G19="25x5",H19*48*1.5)+IF(G19="25x10",H19*55*1.5)+IF(G19="30x5",H19*60*1.5)+IF(G19="30x10",H19*65*1.5)+IF(G19="40x5",H19*65*1.5)+IF(G19="40x10",H19*75*1.5)+IF(G19="50x5",H19*75*1.5)+IF(G19="50x10",H19*85*1.5)+IF(G19="60x5",H19*85*1.5)+IF(G19="60x10",H19*95*1.5)+IF(G19="80x5",H19*110*1.5)+IF(G19="80x10",H19*115*1.5)+IF(G19="100x5",H19*125*1.5)+IF(G19="100x10",H19*135*1.5)+IF(G19="120x5",H19*145*1.5)+IF(G19="120x10",H19*155*1.5)+IF(G19="150x10",H19*185*1.5) -> 0
B20: HL 030 | C20: 6 | D20: =IF(B20="HL 030",C20*'Cost-Sheet'!H17)+IF(B20="HL 027",C20*'Cost-Sheet'!H18)+IF(B20="HL 056",C20*'Cost-Sheet'!H19)+IF(B20="HL 051",C20*'Cost-Sheet'!H20) -> 2700 | I20: =IF(G20="20x5",H20*0.3)+IF(G20="25x5",H20*0.4)+IF(G20="25x10",H20*0.7)+IF(G20="30x5",H20*0.45)+IF(G20="30x10",H20*0.85)+IF(G20="40x5",H20*0.6)+IF(G20="40x10",H20*1.1)+IF(G20="50x5",H20*0.7)+IF(G20="50x10",H20*1.4)+IF(G20="60x5",H20*0.85)+IF(G20="60x10",H20*1.7)+IF(G20="80x5",H20*1.1)+IF(G20="80x10",H20*2.2)+IF(G20="100x5",H20*1.4)+IF(G20="100x10",H20*2.8)+IF(G20="120x5",H20*1.67)+IF(G20="120x10",H20*3.3)+IF(G20="150x10",H20*4.2) -> 0 | J20: =IF(G20="20x5",H20*43*1.5)+IF(G20="25x5",H20*48*1.5)+IF(G20="25x10",H20*55*1.5)+IF(G20="30x5",H20*60*1.5)+IF(G20="30x10",H20*65*1.5)+IF(G20="40x5",H20*65*1.5)+IF(G20="40x10",H20*75*1.5)+IF(G20="50x5",H20*75*1.5)+IF(G20="50x10",H20*85*1.5)+IF(G20="60x5",H20*85*1.5)+IF(G20="60x10",H20*95*1.5)+IF(G20="80x5",H20*110*1.5)+IF(G20="80x10",H20*115*1.5)+IF(G20="100x5",H20*125*1.5)+IF(G20="100x10",H20*135*1.5)+IF(G20="120x5",H20*145*1.5)+IF(G20="120x10",H20*155*1.5)+IF(G20="150x10",H20*185*1.5) -> 0
I21: =IF(G21="20x5",H21*0.3)+IF(G21="25x5",H21*0.4)+IF(G21="25x10",H21*0.7)+IF(G21="30x5",H21*0.45)+IF(G21="30x10",H21*0.85)+IF(G21="40x5",H21*0.6)+IF(G21="40x10",H21*1.1)+IF(G21="50x5",H21*0.7)+IF(G21="50x10",H21*1.4)+IF(G21="60x5",H21*0.85)+IF(G21="60x10",H21*1.7)+IF(G21="80x5",H21*1.1)+IF(G21="80x10",H21*2.2)+IF(G21="100x5",H21*1.4)+IF(G21="100x10",H21*2.8)+IF(G21="120x5",H21*1.67)+IF(G21="120x10",H21*3.3)+IF(G21="150x10",H21*4.2) -> 0 | J21: =IF(G21="20x5",H21*43*1.5)+IF(G21="25x5",H21*48*1.5)+IF(G21="25x10",H21*55*1.5)+IF(G21="30x5",H21*60*1.5)+IF(G21="30x10",H21*65*1.5)+IF(G21="40x5",H21*65*1.5)+IF(G21="40x10",H21*75*1.5)+IF(G21="50x5",H21*75*1.5)+IF(G21="50x10",H21*85*1.5)+IF(G21="60x5",H21*85*1.5)+IF(G21="60x10",H21*95*1.5)+IF(G21="80x5",H21*110*1.5)+IF(G21="80x10",H21*115*1.5)+IF(G21="100x5",H21*125*1.5)+IF(G21="100x10",H21*135*1.5)+IF(G21="120x5",H21*145*1.5)+IF(G21="120x10",H21*155*1.5)+IF(G21="150x10",H21*185*1.5) -> 0
A22: LOCK | B22: Model | C22: Qty | D22: Cost | I22: =IF(G22="20x5",H22*0.3)+IF(G22="25x5",H22*0.4)+IF(G22="25x10",H22*0.7)+IF(G22="30x5",H22*0.45)+IF(G22="30x10",H22*0.85)+IF(G22="40x5",H22*0.6)+IF(G22="40x10",H22*1.1)+IF(G22="50x5",H22*0.7)+IF(G22="50x10",H22*1.4)+IF(G22="60x5",H22*0.85)+IF(G22="60x10",H22*1.7)+IF(G22="80x5",H22*1.1)+IF(G22="80x10",H22*2.2)+IF(G22="100x5",H22*1.4)+IF(G22="100x10",H22*2.8)+IF(G22="120x5",H22*1.67)+IF(G22="120x10",H22*3.3)+IF(G22="150x10",H22*4.2) -> 0 | J22: =IF(G22="20x5",H22*43*1.5)+IF(G22="25x5",H22*48*1.5)+IF(G22="25x10",H22*55*1.5)+IF(G22="30x5",H22*60*1.5)+IF(G22="30x10",H22*65*1.5)+IF(G22="40x5",H22*65*1.5)+IF(G22="40x10",H22*75*1.5)+IF(G22="50x5",H22*75*1.5)+IF(G22="50x10",H22*85*1.5)+IF(G22="60x5",H22*85*1.5)+IF(G22="60x10",H22*95*1.5)+IF(G22="80x5",H22*110*1.5)+IF(G22="80x10",H22*115*1.5)+IF(G22="100x5",H22*125*1.5)+IF(G22="100x10",H22*135*1.5)+IF(G22="120x5",H22*145*1.5)+IF(G22="120x10",H22*155*1.5)+IF(G22="150x10",H22*185*1.5) -> 0
B23: MS 480 | C23: 2 | D23: =IF(B23="MS 480",C23*'Cost-Sheet'!H24)+IF(B23="MS 408",C23*'Cost-Sheet'!H25)+IF(B23="BNL 22",C23*'Cost-Sheet'!H26)+IF(B23="PL 130",C23*'Cost-Sheet'!H27)+IF(B23="PL 150",C23*'Cost-Sheet'!H28) -> 2200 | I23: =IF(G23="20x5",H23*0.3)+IF(G23="25x5",H23*0.4)+IF(G23="25x10",H23*0.7)+IF(G23="30x5",H23*0.45)+IF(G23="30x10",H23*0.85)+IF(G23="40x5",H23*0.6)+IF(G23="40x10",H23*1.1)+IF(G23="50x5",H23*0.7)+IF(G23="50x10",H23*1.4)+IF(G23="60x5",H23*0.85)+IF(G23="60x10",H23*1.7)+IF(G23="80x5",H23*1.1)+IF(G23="80x10",H23*2.2)+IF(G23="100x5",H23*1.4)+IF(G23="100x10",H23*2.8)+IF(G23="120x5",H23*1.67)+IF(G23="120x10",H23*3.3)+IF(G23="150x10",H23*4.2) -> 0 | J23: =IF(G23="20x5",H23*43*1.5)+IF(G23="25x5",H23*48*1.5)+IF(G23="25x10",H23*55*1.5)+IF(G23="30x5",H23*60*1.5)+IF(G23="30x10",H23*65*1.5)+IF(G23="40x5",H23*65*1.5)+IF(G23="40x10",H23*75*1.5)+IF(G23="50x5",H23*75*1.5)+IF(G23="50x10",H23*85*1.5)+IF(G23="60x5",H23*85*1.5)+IF(G23="60x10",H23*95*1.5)+IF(G23="80x5",H23*110*1.5)+IF(G23="80x10",H23*115*1.5)+IF(G23="100x5",H23*125*1.5)+IF(G23="100x10",H23*135*1.5)+IF(G23="120x5",H23*145*1.5)+IF(G23="120x10",H23*155*1.5)+IF(G23="150x10",H23*185*1.5) -> 0
I24: =IF(G24="20x5",H24*0.3)+IF(G24="25x5",H24*0.4)+IF(G24="25x10",H24*0.7)+IF(G24="30x5",H24*0.45)+IF(G24="30x10",H24*0.85)+IF(G24="40x5",H24*0.6)+IF(G24="40x10",H24*1.1)+IF(G24="50x5",H24*0.7)+IF(G24="50x10",H24*1.4)+IF(G24="60x5",H24*0.85)+IF(G24="60x10",H24*1.7)+IF(G24="80x5",H24*1.1)+IF(G24="80x10",H24*2.2)+IF(G24="100x5",H24*1.4)+IF(G24="100x10",H24*2.8)+IF(G24="120x5",H24*1.67)+IF(G24="120x10",H24*3.3)+IF(G24="150x10",H24*4.2) -> 0 | J24: =IF(G24="20x5",H24*43*1.5)+IF(G24="25x5",H24*48*1.5)+IF(G24="25x10",H24*55*1.5)+IF(G24="30x5",H24*60*1.5)+IF(G24="30x10",H24*65*1.5)+IF(G24="40x5",H24*65*1.5)+IF(G24="40x10",H24*75*1.5)+IF(G24="50x5",H24*75*1.5)+IF(G24="50x10",H24*85*1.5)+IF(G24="60x5",H24*85*1.5)+IF(G24="60x10",H24*95*1.5)+IF(G24="80x5",H24*110*1.5)+IF(G24="80x10",H24*115*1.5)+IF(G24="100x5",H24*125*1.5)+IF(G24="100x10",H24*135*1.5)+IF(G24="120x5",H24*145*1.5)+IF(G24="120x10",H24*155*1.5)+IF(G24="150x10",H24*185*1.5) -> 0
A25: ACRYLIC SHEET | B25: Qty | C25: Cost
B26: 0.25 | C26: =B26*'Cost-Sheet'!B23 -> 1250
A28: GAS KIT | B28: Qty | C28: Cost
B29: 85 | C29: =B29*'Cost-Sheet'!B27 -> 552.5
A31: I-Bolt | B31: Qty | C31: Cost
B32: 4 | C32: =B32*'Cost-Sheet'!B31 -> 440
A34: Cable Duct | B34: Model | C34: Qty | D34: Cost
B35: 40x60 | C35: 2.5 | D35: =IF(B35="25x25",C35*'Cost-Sheet'!H32)+IF(B35="25x40",C35*'Cost-Sheet'!H33)+IF(B35="33x33",C35*'Cost-Sheet'!H34)+IF(B35="40x40",C35*'Cost-Sheet'!H35)+IF(B35="40x60",C35*'Cost-Sheet'!H36)+IF(B35="60x40",C35*'Cost-Sheet'!H37)+IF(B35="60x60",C35*'Cost-Sheet'!H38)+IF(B35="80x80",C35*'Cost-Sheet'!H39)+IF(B35="100x100",C35*'Cost-Sheet'!H40) -> 1450
A37: Bus Bar | B37: Weight/kg | C37: Cost | D37: Salve Cost
B38: =SUM(I7:I24) -> 11.975 | C38: =B38*'Cost-Sheet'!B39 -> 26345 | D38: =SUM(J7:J24) -> 2286.75
A40: Wiring Cost | B40: 15000
A42: Labour | B42: 5000
A44: MISC. EXP | B44: 1500
A47: Total Cost | B47: =B12+B15+B17+D20+D23+C26+C29+C32+D35+B40+B42+B44+C38+D38 -> 121884.91 | C47: =C12+B15+B17+D20+D23+C26+C29+C32+D35+B40+B42+B44+C38+D38 -> 110748.91 | D47: =D12+B15+B17+D20+D23+C26+C29+C32+D35+B40+B42+B44+C38+D38 -> 99438.915
A48: INCREASE BY % | B48: 0.03 | C48: 0.03 | D48: 0.03
A49: Final Cost | B49: =B47:B47*(1+B48:B48) -> 125541.46 | C49: =C47:C47*(1+C48:C48) -> 114071.38 | D49: =D47:D47*(1+D48:D48) -> 102422.08
A50: =HYPERLINK(B9) -> MS Sheet | B50: 14SWG | C50: 16SWG | D50: 18SWG

Sheet Cost-Sheet
M4: MS Sheet | P4: 20x5
A5: Last Update Date | G5: Last Update Date | M5: SS Sheet | P5: 25x5
A6: Sheet Price/Kg | B6: MS Sheet | C6: SS Sheet | D6: GI Sheet | G6: Paint Cost | H6: M/F=7032 | I6: M/F7035 | M6: GI Sheet | P6: 25x10
B7: 290 | C7: 900 | D7: 295 | G7: Depth/MM | J7: Update | P7: 30x5
C8: 24.09.2022 | G8: 100-200 | H8: 325 | I8: 437.5 | J8: 13.06.2022 | P8: 30x10
C9: as per imran butt | G9: 250-300 | H9: 350 | I9: 468.75 | J9: 13.06.2022 | P9: 40x5
G10: 350-450 | H10: 437.5 | I10: 562.5 | J10: 13.06.2022 | M10: 7032 | P10: 40x10
G11: 500-600 | H11: 500 | I11: 625 | J11: 13.06.2022 | M11: 7035 | P11: 50x5
G12: 700-800 | H12: 562.5 | I12: 687.5 | J12: 13.06.2022 | P12: 50x10
G13: 900-1200 | H13: 625 | I13: 750 | J13: 13.06.2022 | P13: 60x5
P14: 60x10
G15: Last Update Date | P15: 80x5
G16: HINGES | H16: Price | P16: 80x10
G17: HL 030 | H17: 450 | I17: 24-9-22 | P17: 100x5
G18: HL 027 | H18: 300 | I18: 24-9-22 | P18: 100x10
G19: HL 056 | H19: 350 | P19: 120x5
G20: HL 051 | H20: 150 | P20: 120x10
A21: Last Update Date | P21: 150x10
A22: ACRYLIC SHEET | B22: Cost | G22: Last Update Date
B23: 5000 | G23: Lock | H23: Price
G24: MS 480 | H24: 1100
A25: Last Update Date | G25: MS 408 | H25: 550 | I25: 24-9-22
A26: Gas Kit | B26: Cost | G26: BNL 22 | H26: 90
B27: 6.5 | G27: PL 130 | H27: 130
G28: PL 150 | H28: 150
A29: Last Update Date
A30: I-Bolt | B30: Cost | G30: Last Update Date
B31: 110 | G31: Cable Duct | H31: Price
G32: 25x25 | H32: 270
G33: 25x40 | H33: 370
G34: 33x33 | H34: 400
G35: 40x40 | H35: 530
G36: 40x60 | H36: 580
A37: Last Update Date | G37: 60x40 | H37: 650
A38: Bus Bar/Kg | B38: Cost | G38: 60x60 | H38: 750
B39: 2200 | G39: 80x80 | H39: 1000
G40: 100x100 | H40: 2000
P44: YES | Q44: Floor Mount
E45: =IF(AND(OR(D7=100,D7=125,D7=130,D7=150,D7=160,D7=200),A22=7035),'[1]Cost-Sheet'!I8*B7*C7/645.16/144) -> FALSE | P45: NO | Q45: Wall Mount
A46: Door-1
...

Sheet 102025-1
A1: Date | B1: 27.09.2022
A2: Sale Case | B2: MT-2280-2022-09-26--102025
A3: Cilent | B3: Haji Ramzan Cold Storage -1
A6: Panel Size | B6: H | C6: W | D6: D | E6: Cover Plate | G6: Bus Bar | H6: Qty(Feet) | I6: Weight | J6: Saleeve Cost
B7: 1800 | C7: 1400 | D7: 700 | G7: 50x5 | H7: 8 | I7: =IF(G7="20x5",H7*0.3)+IF(G7="25x5",H7*0.4)+IF(G7="25x10",H7*0.7)+IF(G7="30x5",H7*0.45)+IF(G7="30x10",H7*0.85)+IF(G7="40x5",H7*0.6)+IF(G7="40x10",H7*1.1)+IF(G7="50x5",H7*0.7)+IF(G7="50x10",H7*1.4)+IF(G7="60x5",H7*0.85)+IF(G7="60x10",H7*1.7)+IF(G7="80x5",H7*1.1)+IF(G7="80x10",H7*2.2)+IF(G7="100x5",H7*1.4)+IF(G7="100x10",H7*2.8)+IF(G7="120x5",H7*1.67)+IF(G7="120x10",H7*3.3)+IF(G7="150x10",H7*4.2) -> 5.6 | J7: =IF(G7="20x5",H7*43*1.5)+IF(G7="25x5",H7*48*1.5)+IF(G7="25x10",H7*55*1.5)+IF(G7="30x5",H7*60*1.5)+IF(G7="30x10",H7*65*1.5)+IF(G7="40x5",H7*65*1.5)+IF(G7="40x10",H7*75*1.5)+IF(G7="50x5",H7*75*1.5)+IF(G7="50x10",H7*85*1.5)+IF(G7="60x5",H7*85*1.5)+IF(G7="60x10",H7*95*1.5)+IF(G7="80x5",H7*110*1.5)+IF(G7="80x10",H7*115*1.5)+IF(G7="100x5",H7*125*1.5)+IF(G7="100x10",H7*135*1.5)+IF(G7="120x5",H7*145*1.5)+IF(G7="120x10",H7*155*1.5)+IF(G7="150x10",H7*185*1.5) -> 900
A8: Panel Type | B8: Floor Mount | C8: Canopy | D8: YES | G8: 30x10 | H8: 8 | I8: =IF(G8="20x5",H8*0.3)+IF(G8="25x5",H8*0.4)+IF(G8="25x10",H8*0.7)+IF(G8="30x5",H8*0.45)+IF(G8="30x10",H8*0.85)+IF(G8="40x5",H8*0.6)+IF(G8="40x10",H8*1.1)+IF(G8="50x5",H8*0.7)+IF(G8="50x10",H8*1.4)+IF(G8="60x5",H8*0.85)+IF(G8="60x10",H8*1.7)+IF(G8="80x5",H8*1.1)+IF(G8="80x10",H8*2.2)+IF(G8="100x5",H8*1.4)+IF(G8="100x10",H8*2.8)+IF(G8="120x5",H8*1.67)+IF(G8="120x10",H8*3.3)+IF(G8="150x10",H8*4.2) -> 6.8 | J8: =IF(G8="20x5",H8*43*1.5)+IF(G8="25x5",H8*48*1.5)+IF(G8="25x10",H8*55*1.5)+IF(G8="30x5",H8*60*1.5)+IF(G8="30x10",H8*65*1.5)+IF(G8="40x5",H8*65*1.5)+IF(G8="40x10",H8*75*1.5)+IF(G8="50x5",H8*75*1.5)+IF(G8="50x10",H8*85*1.5)+IF(G8="60x5",H8*85*1.5)+IF(G8="60x10",H8*95*1.5)+IF(G8="80x5",H8*110*1.5)+IF(G8="80x10",H8*115*1.5)+IF(G8="100x5",H8*125*1.5)+IF(G8="100x10",H8*135*1.5)+IF(G8="120x5",H8*145*1.5)+IF(G8="120x10",H8*155*1.5)+IF(G8="150x10",H8*185*1.5) -> 780
A9: Door#1 | B9: 1800 | C9: 600 | D9: 700 | E9: YES | G9: 25x5 | H9: 5 | I9: =IF(G9="20x5",H9*0.3)+IF(G9="25x5",H9*0.4)+IF(G9="25x10",H9*0.7)+IF(G9="30x5",H9*0.45)+IF(G9="30x10",H9*0.85)+IF(G9="40x5",H9*0.6)+IF(G9="40x10",H9*1.1)+IF(G9="50x5",H9*0.7)+IF(G9="50x10",H9*1.4)+IF(G9="60x5",H9*0.85)+IF(G9="60x10",H9*1.7)+IF(G9="80x5",H9*1.1)+IF(G9="80x10",H9*2.2)+IF(G9="100x5",H9*1.4)+IF(G9="100x10",H9*2.8)+IF(G9="120x5",H9*1.67)+IF(G9="120x10",H9*3.3)+IF(G9="150x10",H9*4.2) -> 2 | J9: =IF(G9="20x5",H9*43*1.5)+IF(G9="25x5",H9*48*1.5)+IF(G9="25x10",H9*55*1.5)+IF(G9="30x5",H9*60*1.5)+IF(G9="30x10",H9*65*1.5)+IF(G9="40x5",H9*65*1.5)+IF(G9="40x10",H9*75*1.5)+IF(G9="50x5",H9*75*1.5)+IF(G9="50x10",H9*85*1.5)+IF(G9="60x5",H9*85*1.5)+IF(G9="60x10",H9*95*1.5)+IF(G9="80x5",H9*110*1.5)+IF(G9="80x10",H9*115*1.5)+IF(G9="100x5",H9*125*1.5)+IF(G9="100x10",H9*135*1.5)+IF(G9="120x5",H9*145*1.5)+IF(G9="120x10",H9*155*1.5)+IF(G9="150x10",H9*185*1.5) -> 360
A10: Door#2 | B10: 1800 | C10: 700 | D10: 700 | E10: YES | G10: 25x5 | H10: 15 | I10: =IF(G10="20x5",H10*0.3)+IF(G10="25x5",H10*0.4)+IF(G10="25x10",H10*0.7)+IF(G10="30x5",H10*0.45)+IF(G10="30x10",H10*0.85)+IF(G10="40x5",H10*0.6)+IF(G10="40x10",H10*1.1)+IF(G10="50x5",H10*0.7)+IF(G10="50x10",H10*1.4)+IF(G10="60x5",H10*0.85)+IF(G10="60x10",H10*1.7)+IF(G10="80x5",H10*1.1)+IF(G10="80x10",H10*2.2)+IF(G10="100x5",H10*1.4)+IF(G10="100x10",H10*2.8)+IF(G10="120x5",H10*1.67)+IF(G10="120x10",H10*3.3)+IF(G10="150x10",H10*4.2) -> 6 | J10: =IF(G10="20x5",H10*43*1.5)+IF(G10="25x5",H10*48*1.5)+IF(G10="25x10",H10*55*1.5)+IF(G10="30x5",H10*60*1.5)+IF(G10="30x10",H10*65*1.5)+IF(G10="40x5",H10*65*1.5)+IF(G10="40x10",H10*75*1.5)+IF(G10="50x5",H10*75*1.5)+IF(G10="50x10",H10*85*1.5)+IF(G10="60x5",H10*85*1.5)+IF(G10="60x10",H10*95*1.5)+IF(G10="80x5",H10*110*1.5)+IF(G10="80x10",H10*115*1.5)+IF(G10="100x5",H10*125*1.5)+IF(G10="100x10",H10*135*1.5)+IF(G10="120x5",H10*145*1.5)+IF(G10="120x10",H10*155*1.5)+IF(G10="150x10",H10*185*1.5) -> 1080
A11: Door#3 | B11: 0 | C11: 0 | D11: 0 | E11: NO | I11: =IF(G11="20x5",H11*0.3)+IF(G11="25x5",H11*0.4)+IF(G11="25x10",H11*0.7)+IF(G11="30x5",H11*0.45)+IF(G11="30x10",H11*0.85)+IF(G11="40x5",H11*0.6)+IF(G11="40x10",H11*1.1)+IF(G11="50x5",H11*0.7)+IF(G11="50x10",H11*1.4)+IF(G11="60x5",H11*0.85)+IF(G11="60x10",H11*1.7)+IF(G11="80x5",H11*1.1)+IF(G11="80x10",H11*2.2)+IF(G11="100x5",H11*1.4)+IF(G11="100x10",H11*2.8)+IF(G11="120x5",H11*1.67)+IF(G11="120x10",H11*3.3)+IF(G11="150x10",H11*4.2) -> 0 | J11: =IF(G11="20x5",H11*43*1.5)+IF(G11="25x5",H11*48*1.5)+IF(G11="25x10",H11*55*1.5)+IF(G11="30x5",H11*60*1.5)+IF(G11="30x10",H11*65*1.5)+IF(G11="40x5",H11*65*1.5)+IF(G11="40x10",H11*75*1.5)+IF(G11="50x5",H11*75*1.5)+IF(G11="50x10",H11*85*1.5)+IF(G11="60x5",H11*85*1.5)+IF(G11="60x10",H11*95*1.5)+IF(G11="80x5",H11*110*1.5)+IF(G11="80x10",H11*115*1.5)+IF(G11="100x5",H11*125*1.5)+IF(G11="100x10",H11*135*1.5)+IF(G11="120x5",H11*145*1.5)+IF(G11="120x10",H11*155*1.5)+IF(G11="150x10",H11*185*1.5) -> 0
A12: Door#4 | B12: 0 | C12: 0 | D12: 0 | E12: NO | I12: =IF(G12="20x5",H12*0.3)+IF(G12="25x5",H12*0.4)+IF(G12="25x10",H12*0.7)+IF(G12="30x5",H12*0.45)+IF(G12="30x10",H12*0.85)+IF(G12="40x5",H12*0.6)+IF(G12="40x10",H12*1.1)+IF(G12="50x5",H12*0.7)+IF(G12="50x10",H12*1.4)+IF(G12="60x5",H12*0.85)+IF(G12="60x10",H12*1.7)+IF(G12="80x5",H12*1.1)+IF(G12="80x10",H12*2.2)+IF(G12="100x5",H12*1.4)+IF(G12="100x10",H12*2.8)+IF(G12="120x5",H12*1.67)+IF(G12="120x10",H12*3.3)+IF(G12="150x10",H12*4.2) -> 0 | J12: =IF(G12="20x5",H12*43*1.5)+IF(G12="25x5",H12*48*1.5)+IF(G12="25x10",H12*55*1.5)+IF(G12="30x5",H12*60*1.5)+IF(G12="30x10",H12*65*1.5)+IF(G12="40x5",H12*65*1.5)+IF(G12="40x10",H12*75*1.5)+IF(G12="50x5",H12*75*1.5)+IF(G12="50x10",H12*85*1.5)+IF(G12="60x5",H12*85*1.5)+IF(G12="60x10",H12*95*1.5)+IF(G12="80x5",H12*110*1.5)+IF(G12="80x10",H12*115*1.5)+IF(G12="100x5",H12*125*1.5)+IF(G12="100x10",H12*135*1.5)+IF(G12="120x5",H12*145*1.5)+IF(G12="120x10",H12*155*1.5)+IF(G12="150x10",H12*185*1.5) -> 0
A13: Door#5 | B13: 0 | C13: 0 | D13: 0 | E13: NO | I13: =IF(G13="20x5",H13*0.3)+IF(G13="25x5",H13*0.4)+IF(G13="25x10",H13*0.7)+IF(G13="30x5",H13*0.45)+IF(G13="30x10",H13*0.85)+IF(G13="40x5",H13*0.6)+IF(G13="40x10",H13*1.1)+IF(G13="50x5",H13*0.7)+IF(G13="50x10",H13*1.4)+IF(G13="60x5",H13*0.85)+IF(G13="60x10",H13*1.7)+IF(G13="80x5",H13*1.1)+IF(G13="80x10",H13*2.2)+IF(G13="100x5",H13*1.4)+IF(G13="100x10",H13*2.8)+IF(G13="120x5",H13*1.67)+IF(G13="120x10",H13*3.3)+IF(G13="150x10",H13*4.2) -> 0 | J13: =IF(G13="20x5",H13*43*1.5)+IF(G13="25x5",H13*48*1.5)+IF(G13="25x10",H13*55*1.5)+IF(G13="30x5",H13*60*1.5)+IF(G13="30x10",H13*65*1.5)+IF(G13="40x5",H13*65*1.5)+IF(G13="40x10",H13*75*1.5)+IF(G13="50x5",H13*75*1.5)+IF(G13="50x10",H13*85*1.5)+IF(G13="60x5",H13*85*1.5)+IF(G13="60x10",H13*95*1.5)+IF(G13="80x5",H13*110*1.5)+IF(G13="80x10",H13*115*1.5)+IF(G13="100x5",H13*125*1.5)+IF(G13="100x10",H13*135*1.5)+IF(G13="120x5",H13*145*1.5)+IF(G13="120x10",H13*155*1.5)+IF(G13="150x10",H13*185*1.5) -> 0
A14: Door#6 | B14: 0 | C14: 0 | D14: 0 | E14: NO | I14: =IF(G14="20x5",H14*0.3)+IF(G14="25x5",H14*0.4)+IF(G14="25x10",H14*0.7)+IF(G14="30x5",H14*0.45)+IF(G14="30x10",H14*0.85)+IF(G14="40x5",H14*0.6)+IF(G14="40x10",H14*1.1)+IF(G14="50x5",H14*0.7)+IF(G14="50x10",H14*1.4)+IF(G14="60x5",H14*0.85)+IF(G14="60x10",H14*1.7)+IF(G14="80x5",H14*1.1)+IF(G14="80x10",H14*2.2)+IF(G14="100x5",H14*1.4)+IF(G14="100x10",H14*2.8)+IF(G14="120x5",H14*1.67)+IF(G14="120x10",H14*3.3)+IF(G14="150x10",H14*4.2) -> 0 | J14: =IF(G14="20x5",H14*43*1.5)+IF(G14="25x5",H14*48*1.5)+IF(G14="25x10",H14*55*1.5)+IF(G14="30x5",H14*60*1.5)+IF(G14="30x10",H14*65*1.5)+IF(G14="40x5",H14*65*1.5)+IF(G14="40x10",H14*75*1.5)+IF(G14="50x5",H14*75*1.5)+IF(G14="50x10",H14*85*1.5)+IF(G14="60x5",H14*85*1.5)+IF(G14="60x10",H14*95*1.5)+IF(G14="80x5",H14*110*1.5)+IF(G14="80x10",H14*115*1.5)+IF(G14="100x5",H14*125*1.5)+IF(G14="100x10",H14*135*1.5)+IF(G14="120x5",H14*145*1.5)+IF(G14="120x10",H14*155*1.5)+IF(G14="150x10",H14*185*1.5) -> 0
A15: Sheet Use | B15: =HYPERLINK('Cost-Sheet'!M154) -> 8.379415 | I15: =IF(G15="20x5",H15*0.3)+IF(G15="25x5",H15*0.4)+IF(G15="25x10",H15*0.7)+IF(G15="30x5",H15*0.45)+IF(G15="30x10",H15*0.85)+IF(G15="40x5",H15*0.6)+IF(G15="40x10",H15*1.1)+IF(G15="50x5",H15*0.7)+IF(G15="50x10",H15*1.4)+IF(G15="60x5",H15*0.85)+IF(G15="60x10",H15*1.7)+IF(G15="80x5",H15*1.1)+IF(G15="80x10",H15*2.2)+IF(G15="100x5",H15*1.4)+IF(G15="100x10",H15*2.8)+IF(G15="120x5",H15*1.67)+IF(G15="120x10",H15*3.3)+IF(G15="150x10",H15*4.2) -> 0 | J15: =IF(G15="20x5",H15*43*1.5)+IF(G15="25x5",H15*48*1.5)+IF(G15="25x10",H15*55*1.5)+IF(G15="30x5",H15*60*1.5)+IF(G15="30x10",H15*65*1.5)+IF(G15="40x5",H15*65*1.5)+IF(G15="40x10",H15*75*1.5)+IF(G15="50x5",H15*75*1.5)+IF(G15="50x10",H15*85*1.5)+IF(G15="60x5",H15*85*1.5)+IF(G15="60x10",H15*95*1.5)+IF(G15="80x5",H15*110*1.5)+IF(G15="80x10",H15*115*1.5)+IF(G15="100x5",H15*125*1.5)+IF(G15="100x10",H15*135*1.5)+IF(G15="120x5",H15*145*1.5)+IF(G15="120x10",H15*155*1.5)+IF(G15="150x10",H15*185*1.5) -> 0
A16: Sheet Selection | B16: MS Sheet | I16: =IF(G16="20x5",H16*0.3)+IF(G16="25x5",H16*0.4)+IF(G16="25x10",H16*0.7)+IF(G16="30x5",H16*0.45)+IF(G16="30x10",H16*0.85)+IF(G16="40x5",H16*0.6)+IF(G16="40x10",H16*1.1)+IF(G16="50x5",H16*0.7)+IF(G16="50x10",H16*1.4)+IF(G16="60x5",H16*0.85)+IF(G16="60x10",H16*1.7)+IF(G16="80x5",H16*1.1)+IF(G16="80x10",H16*2.2)+IF(G16="100x5",H16*1.4)+IF(G16="100x10",H16*2.8)+IF(G16="120x5",H16*1.67)+IF(G16="120x10",H16*3.3)+IF(G16="150x10",H16*4.2) -> 0 | J16: =IF(G16="20x5",H16*43*1.5)+IF(G16="25x5",H16*48*1.5)+IF(G16="25x10",H16*55*1.5)+IF(G16="30x5",H16*60*1.5)+IF(G16="30x10",H16*65*1.5)+IF(G16="40x5",H16*65*1.5)+IF(G16="40x10",H16*75*1.5)+IF(G16="50x5",H16*75*1.5)+IF(G16="50x10",H16*85*1.5)+IF(G16="60x5",H16*85*1.5)+IF(G16="60x10",H16*95*1.5)+IF(G16="80x5",H16*110*1.5)+IF(G16="80x10",H16*115*1.5)+IF(G16="100x5",H16*125*1.5)+IF(G16="100x10",H16*135*1.5)+IF(G16="120x5",H16*145*1.5)+IF(G16="120x10",H16*155*1.5)+IF(G16="150x10",H16*185*1.5) -> 0
A17: Sheet SWG | B17: 14SWG | C17: 16SWG | D17: 18SWG | I17: =IF(G17="20x5",H17*0.3)+IF(G17="25x5",H17*0.4)+IF(G17="25x10",H17*0.7)+IF(G17="30x5",H17*0.45)+IF(G17="30x10",H17*0.85)+IF(G17="40x5",H17*0.6)+IF(G17="40x10",H17*1.1)+IF(G17="50x5",H17*0.7)+IF(G17="50x10",H17*1.4)+IF(G17="60x5",H17*0.85)+IF(G17="60x10",H17*1.7)+IF(G17="80x5",H17*1.1)+IF(G17="80x10",H17*2.2)+IF(G17="100x5",H17*1.4)+IF(G17="100x10",H17*2.8)+IF(G17="120x5",H17*1.67)+IF(G17="120x10",H17*3.3)+IF(G17="150x10",H17*4.2) -> 0 | J17: =IF(G17="20x5",H17*43*1.5)+IF(G17="25x5",H17*48*1.5)+IF(G17="25x10",H17*55*1.5)+IF(G17="30x5",H17*60*1.5)+IF(G17="30x10",H17*65*1.5)+IF(G17="40x5",H17*65*1.5)+IF(G17="40x10",H17*75*1.5)+IF(G17="50x5",H17*75*1.5)+IF(G17="50x10",H17*85*1.5)+IF(G17="60x5",H17*85*1.5)+IF(G17="60x10",H17*95*1.5)+IF(G17="80x5",H17*110*1.5)+IF(G17="80x10",H17*115*1.5)+IF(G17="100x5",H17*125*1.5)+IF(G17="100x10",H17*135*1.5)+IF(G17="120x5",H17*145*1.5)+IF(G17="120x10",H17*155*1.5)+IF(G17="150x10",H17*185*1.5) -> 0
A18: Sheet Weight | B18: =B15*48.64 -> 407.57475 | C18: =B15*38.4 -> 321.76954 | D18: =B15*28 -> 234.62362 | I18: =IF(G18="20x5",H18*0.3)+IF(G18="25x5",H18*0.4)+IF(G18="25x10",H18*0.7)+IF(G18="30x5",H18*0.45)+IF(G18="30x10",H18*0.85)+IF(G18="40x5",H18*0.6)+IF(G18="40x10",H18*1.1)+IF(G18="50x5",H18*0.7)+IF(G18="50x10",H18*1.4)+IF(G18="60x5",H18*0.85)+IF(G18="60x10",H18*1.7)+IF(G18="80x5",H18*1.1)+IF(G18="80x10",H18*2.2)+IF(G18="100x5",H18*1.4)+IF(G18="100x10",H18*2.8)+IF(G18="120x5",H18*1.67)+IF(G18="120x10",H18*3.3)+IF(G18="150x10",H18*4.2) -> 0 | J18: =IF(G18="20x5",H18*43*1.5)+IF(G18="25x5",H18*48*1.5)+IF(G18="25x10",H18*55*1.5)+IF(G18="30x5",H18*60*1.5)+IF(G18="30x10",H18*65*1.5)+IF(G18="40x5",H18*65*1.5)+IF(G18="40x10",H18*75*1.5)+IF(G18="50x5",H18*75*1.5)+IF(G18="50x10",H18*85*1.5)+IF(G18="60x5",H18*85*1.5)+IF(G18="60x10",H18*95*1.5)+IF(G18="80x5",H18*110*1.5)+IF(G18="80x10",H18*115*1.5)+IF(G18="100x5",H18*125*1.5)+IF(G18="100x10",H18*135*1.5)+IF(G18="120x5",H18*145*1.5)+IF(G18="120x10",H18*155*1.5)+IF(G18="150x10",H18*185*1.5) -> 0
A19: Sheet Cost | B19: =IF(B16="MS Sheet",B18*'Cost-Sheet'!B7)+IF(B16="SS Sheet",B18*'Cost-Sheet'!C7)+IF(B16="GI Sheet",B18*'Cost-Sheet'!D7) -> 118196.68 | C19: =IF(B16="MS Sheet",C18*'Cost-Sheet'!B7)+IF(B16="SS Sheet",C18*'Cost-Sheet'!C7)+IF(B16="GI Sheet",C18*'Cost-Sheet'!D7) -> 93313.165 | D19: =IF(B16="MS Sheet",D18*'Cost-Sheet'!B7)+IF(B16="SS Sheet",D18*'Cost-Sheet'!C7)+IF(B16="GI Sheet",D18*'Cost-Sheet'!D7) -> 68040.85 | I19: =IF(G19="20x5",H19*0.3)+IF(G19="25x5",H19*0.4)+IF(G19="25x10",H19*0.7)+IF(G19="30x5",H19*0.45)+IF(G19="30x10",H19*0.85)+IF(G19="40x5",H19*0.6)+IF(G19="40x10",H19*1.1)+IF(G19="50x5",H19*0.7)+IF(G19="50x10",H19*1.4)+IF(G19="60x5",H19*0.85)+IF(G19="60x10",H19*1.7)+IF(G19="80x5",H19*1.1)+IF(G19="80x10",H19*2.2)+IF(G19="100x5",H19*1.4)+IF(G19="100x10",H19*2.8)+IF(G19="120x5",H19*1.67)+IF(G19="120x10",H19*3.3)+IF(G19="150x10",H19*4.2) -> 0 | J19: =IF(G19="20x5",H19*43*1.5)+IF(G19="25x5",H19*48*1.5)+IF(G19="25x10",H19*55*1.5)+IF(G19="30x5",H19*60*1.5)+IF(G19="30x10",H19*65*1.5)+IF(G19="40x5",H19*65*1.5)+IF(G19="40x10",H19*75*1.5)+IF(G19="50x5",H19*75*1.5)+IF(G19="50x10",H19*85*1.5)+IF(G19="60x5",H19*85*1.5)+IF(G19="60x10",H19*95*1.5)+IF(G19="80x5",H19*110*1.5)+IF(G19="80x10",H19*115*1.5)+IF(G19="100x5",H19*125*1.5)+IF(G19="100x10",H19*135*1.5)+IF(G19="120x5",H19*145*1.5)+IF(G19="120x10",H19*155*1.5)+IF(G19="150x10",H19*185*1.5) -> 0
I20: =IF(G20="20x5",H20*0.3)+IF(G20="25x5",H20*0.4)+IF(G20="25x10",H20*0.7)+IF(G20="30x5",H20*0.45)+IF(G20="30x10",H20*0.85)+IF(G20="40x5",H20*0.6)+IF(G20="40x10",H20*1.1)+IF(G20="50x5",H20*0.7)+IF(G20="50x10",H20*1.4)+IF(G20="60x5",H20*0.85)+IF(G20="60x10",H20*1.7)+IF(G20="80x5",H20*1.1)+IF(G20="80x10",H20*2.2)+IF(G20="100x5",H20*1.4)+IF(G20="100x10",H20*2.8)+IF(G20="120x5",H20*1.67)+IF(G20="120x10",H20*3.3)+IF(G20="150x10",H20*4.2) -> 0 | J20: =IF(G20="20x5",H20*43*1.5)+IF(G20="25x5",H20*48*1.5)+IF(G20="25x10",H20*55*1.5)+IF(G20="30x5",H20*60*1.5)+IF(G20="30x10",H20*65*1.5)+IF(G20="40x5",H20*65*1.5)+IF(G20="40x10",H20*75*1.5)+IF(G20="50x5",H20*75*1.5)+IF(G20="50x10",H20*85*1.5)+IF(G20="60x5",H20*85*1.5)+IF(G20="60x10",H20*95*1.5)+IF(G20="80x5",H20*110*1.5)+IF(G20="80x10",H20*115*1.5)+IF(G20="100x5",H20*125*1.5)+IF(G20="100x10",H20*135*1.5)+IF(G20="120x5",H20*145*1.5)+IF(G20="120x10",H20*155*1.5)+IF(G20="150x10",H20*185*1.5) -> 0
A21: Paint Cost | I21: =IF(G21="20x5",H21*0.3)+IF(G21="25x5",H21*0.4)+IF(G21="25x10",H21*0.7)+IF(G21="30x5",H21*0.45)+IF(G21="30x10",H21*0.85)+IF(G21="40x5",H21*0.6)+IF(G21="40x10",H21*1.1)+IF(G21="50x5",H21*0.7)+IF(G21="50x10",H21*1.4)+IF(G21="60x5",H21*0.85)+IF(G21="60x10",H21*1.7)+IF(G21="80x5",H21*1.1)+IF(G21="80x10",H21*2.2)+IF(G21="100x5",H21*1.4)+IF(G21="100x10",H21*2.8)+IF(G21="120x5",H21*1.67)+IF(G21="120x10",H21*3.3)+IF(G21="150x10",H21*4.2) -> 0 | J21: =IF(G21="20x5",H21*43*1.5)+IF(G21="25x5",H21*48*1.5)+IF(G21="25x10",H21*55*1.5)+IF(G21="30x5",H21*60*1.5)+IF(G21="30x10",H21*65*1.5)+IF(G21="40x5",H21*65*1.5)+IF(G21="40x10",H21*75*1.5)+IF(G21="50x5",H21*75*1.5)+IF(G21="50x10",H21*85*1.5)+IF(G21="60x5",H21*85*1.5)+IF(G21="60x10",H21*95*1.5)+IF(G21="80x5",H21*110*1.5)+IF(G21="80x10",H21*115*1.5)+IF(G21="100x5",H21*125*1.5)+IF(G21="100x10",H21*135*1.5)+IF(G21="120x5",H21*145*1.5)+IF(G21="120x10",H21*155*1.5)+IF(G21="150x10",H21*185*1.5) -> 0
A22: 7035 | B22: =IF(AND(OR(D7=100,D7=125,D7=130,D7=150,D7=160,D7=200),A22=7035),'Cost-Sheet'!I8*B7*C7/645.16/144)+IF(AND(OR(D7=250,D7=300),A22=7035),'Cost-Sheet'!I9*B7*C7/645.16/144)+IF(AND(OR(D7=350,D7=380,D7=400,D7=450),A22=7035),'Cost-Sheet'!I10*B7*C7/645.16/144)+IF(AND(OR(D7=500,D7=600),A22=7035),'Cost-Sheet'!I11*B7*C7/645.16/144)+IF(AND(OR(D7=700,D7=750,D7=800),A22=7035),'Cost-Sheet'!I12*B7*C7/645.16/144)+IF(AND(OR(D7=900,D7=1000,D7=1100,D7=1200),A22=7035),'Cost-Sheet'!I13*B7*C7/645.16/144)+IF(AND(OR(D7=100,D7=125,D7=130,D7=150,D7=160,D7=200),A22=7032),'Cost-Sheet'!H8*B7*C7/645.16/144)+IF(AND(OR(D7=250,D7=300),A22=7032),'Cost-Sheet'!H9*B7*C7/645.16/144)+IF(AND(OR(D7=350,D7=380,D7=400,D7=450),A22=7032),'Cost-Sheet'!H10*B7*C7/645.16/144)+IF(AND(OR(D7=500,D7=600),A22=7032),'Cost-Sheet'!H11*B7*C7/645.16/144)+IF(AND(OR(D7=700,D7=750,D7=800),A22=7032),'Cost-Sheet'!H12*B7*C7/645.16/144)+IF(AND(OR(D7=900,D7=1000,D7=1100,D7=1200),A22=7032),'Cost-Sheet'!H13*B7*C7/645.16/144) -> 18648.475 | I22: =IF(G22="20x5",H22*0.3)+IF(G22="25x5",H22*0.4)+IF(G22="25x10",H22*0.7)+IF(G22="30x5",H22*0.45)+IF(G22="30x10",H22*0.85)+IF(G22="40x5",H22*0.6)+IF(G22="40x10",H22*1.1)+IF(G22="50x5",H22*0.7)+IF(G22="50x10",H22*1.4)+IF(G22="60x5",H22*0.85)+IF(G22="60x10",H22*1.7)+IF(G22="80x5",H22*1.1)+IF(G22="80x10",H22*2.2)+IF(G22="100x5",H22*1.4)+IF(G22="100x10",H22*2.8)+IF(G22="120x5",H22*1.67)+IF(G22="120x10",H22*3.3)+IF(G22="150x10",H22*4.2) -> 0 | J22: =IF(G22="20x5",H22*43*1.5)+IF(G22="25x5",H22*48*1.5)+IF(G22="25x10",H22*55*1.5)+IF(G22="30x5",H22*60*1.5)+IF(G22="30x10",H22*65*1.5)+IF(G22="40x5",H22*65*1.5)+IF(G22="40x10",H22*75*1.5)+IF(G22="50x5",H22*75*1.5)+IF(G22="50x10",H22*85*1.5)+IF(G22="60x5",H22*85*1.5)+IF(G22="60x10",H22*95*1.5)+IF(G22="80x5",H22*110*1.5)+IF(G22="80x10",H22*115*1.5)+IF(G22="100x5",H22*125*1.5)+IF(G22="100x10",H22*135*1.5)+IF(G22="120x5",H22*145*1.5)+IF(G22="120x10",H22*155*1.5)+IF(G22="150x10",H22*185*1.5) -> 0
I23: =IF(G23="20x5",H23*0.3)+IF(G23="25x5",H23*0.4)+IF(G23="25x10",H23*0.7)+IF(G23="30x5",H23*0.45)+IF(G23="30x10",H23*0.85)+IF(G23="40x5",H23*0.6)+IF(G23="40x10",H23*1.1)+IF(G23="50x5",H23*0.7)+IF(G23="50x10",H23*1.4)+IF(G23="60x5",H23*0.85)+IF(G23="60x10",H23*1.7)+IF(G23="80x5",H23*1.1)+IF(G23="80x10",H23*2.2)+IF(G23="100x5",H23*1.4)+IF(G23="100x10",H23*2.8)+IF(G23="120x5",H23*1.67)+IF(G23="120x10",H23*3.3)+IF(G23="150x10",H23*4.2) -> 0 | J23: =IF(G23="20x5",H23*43*1.5)+IF(G23="25x5",H23*48*1.5)+IF(G23="25x10",H23*55*1.5)+IF(G23="30x5",H23*60*1.5)+IF(G23="30x10",H23*65*1.5)+IF(G23="40x5",H23*65*1.5)+IF(G23="40x10",H23*75*1.5)+IF(G23="50x5",H23*75*1.5)+IF(G23="50x10",H23*85*1.5)+IF(G23="60x5",H23*85*1.5)+IF(G23="60x10",H23*95*1.5)+IF(G23="80x5",H23*110*1.5)+IF(G23="80x10",H23*115*1.5)+IF(G23="100x5",H23*125*1.5)+IF(G23="100x10",H23*135*1.5)+IF(G23="120x5",H23*145*1.5)+IF(G23="120x10",H23*155*1.5)+IF(G23="150x10",H23*185*1.5) -> 0
A24: Rent | B24: 4000 | I24: =IF(G24="20x5",H24*0.3)+IF(G24="25x5",H24*0.4)+IF(G24="25x10",H24*0.7)+IF(G24="30x5",H24*0.45)+IF(G24="30x10",H24*0.85)+IF(G24="40x5",H24*0.6)+IF(G24="40x10",H24*1.1)+IF(G24="50x5",H24*0.7)+IF(G24="50x10",H24*1.4)+IF(G24="60x5",H24*0.85)+IF(G24="60x10",H24*1.7)+IF(G24="80x5",H24*1.1)+IF(G24="80x10",H24*2.2)+IF(G24="100x5",H24*1.4)+IF(G24="100x10",H24*2.8)+IF(G24="120x5",H24*1.67)+IF(G24="120x10",H24*3.3)+IF(G24="150x10",H24*4.2) -> 0 | J24: =IF(G24="20x5",H24*43*1.5)+IF(G24="25x5",H24*48*1.5)+IF(G24="25x10",H24*55*1.5)+IF(G24="30x5",H24*60*1.5)+IF(G24="30x10",H24*65*1.5)+IF(G24="40x5",H24*65*1.5)+IF(G24="40x10",H24*75*1.5)+IF(G24="50x5",H24*75*1.5)+IF(G24="50x10",H24*85*1.5)+IF(G24="60x5",H24*85*1.5)+IF(G24="60x10",H24*95*1.5)+IF(G24="80x5",H24*110*1.5)+IF(G24="80x10",H24*115*1.5)+IF(G24="100x5",H24*125*1.5)+IF(G24="100x10",H24*135*1.5)+IF(G24="120x5",H24*145*1.5)+IF(G24="120x10",H24*155*1.5)+IF(G24="150x10",H24*185*1.5) -> 0
A26: HINGES | B26: Model | C26: Qty | D26: Cost
B27: HL 030 | C27: 2 | D27: =IF(B27="HL 030",C27*'Cost-Sheet'!H17)+IF(B27="HL 027",C27*'Cost-Sheet'!H18)+IF(B27="HL 056",C27*'Cost-Sheet'!H19)+IF(B27="HL 051",C27*'Cost-Sheet'!H20) -> 900
A29: LOCK | B29: Model | C29: Qty | D29: Cost
B30: MS 408 | C30: 2 | D30: =IF(B30="MS 480",C30*'Cost-Sheet'!H24)+IF(B30="MS 408",C30*'Cost-Sheet'!H25)+IF(B30="BNL 22",C30*'Cost-Sheet'!H26)+IF(B30="PL 130",C30*'Cost-Sheet'!H27)+IF(B30="PL 150",C30*'Cost-Sheet'!H28) -> 1100 | F30: =IF(B30="MS 408",C30*'Cost-Sheet'!H25) -> 1100
A32: ACRYLIC SHEET | B32: Qty | C32: Cost
B33: 0.1 | C33: =B33*'Cost-Sheet'!B23 -> 500
A35: GAS KIT | B35: Qty | C35: Cost
B36: 40 | C36: =B36*'Cost-Sheet'!B27 -> 260
A38: I-Bolt | B38: Qty | C38: Cost
B39: 4 | C39: =B39*'Cost-Sheet'!B31 -> 440
A41: Cable Duct | B41: Model | C41: Qty | D41: Cost
B42: 40x60 | C42: 2 | D42: =IF(B42="25x25",C42*'[1]Cost-Sheet'!H32)+IF(B42="25x40",C42*'[1]Cost-Sheet'!H33)+IF(B42="33x33",C42*'[1]Cost-Sheet'!H34)+IF(B42="40x40",C42*'[1]Cost-Sheet'!H35)+IF(B42="40x60",C42*'[1]Cost-Sheet'!H36)+IF(B42="60x40",C42*'[1]Cost-Sheet'!H37)+IF(B42="60x60",C42*'[1]Cost-Sheet'!H38)+IF(B42="80x80",C42*'[1]Cost-Sheet'!H39)+IF(B42="100x100",C42*'[1]Cost-Sheet'!H40) -> 1160
A44: Bus Bar | B44: Weight/kg | C44: Cost | D44: Saleeve Cost
B45: =SUM(I7:I24) -> 20.4 | C45: =B45*'Cost-Sheet'!B39 -> 44880 | D45: =SUM(J7:J24) -> 3120 | E45: =C45+D45 -> 48000
A47: Wiring Cost | B47: 3000
A49: Labour | B49: 7000
A51: MISC. EXP | B51: 5000
A54: Total Cost | B54: =B19+B22+B24+D27+D30+C33+C36+C39+D42+B47+B49+B51+C45+D45 -> 208205.15 | C54: =C19+B22+B24+D27+D30+C33+C36+C39+D42+B47+B49+B51+C45+D45 -> 183321.64 | D54: =D19+B22+B24+D27+D30+C33+C36+C39+D42+B47+B49+B51+C45+D45 -> 158049.32
...

Sheet Cash Demand 
A1: Date: | I1: Doc #
A2: =HYPERLINK('102025-1'!B3) -> Haji Ramzan Cold Storage -1
A3: Sale Case# | B3: =HYPERLINK('102025-1'!B2) -> MT-2280-2022-09-26--102025
A4: Project Budget | I4: Selling
A6: S.No | B6: Expense Head | C6: Unit Cost | D6: Qty | E6: Budgeted Cost | F6: Actual Cost | G6: Profit /Loss | H6: Already Paid | I6: Current Demand | J6: TotalCost
A7: 1 | B7: Bending Cost
A8: 2 | B8: Paint Cost | C8: =HYPERLINK('102025-1'!B22) -> 18648.4747969496 | D8: 2 | E8: =D8*C8 -> 37296.95 | F8: 38000 | G8: =E8-F8 -> -703.05041
A9: 3 | B9: HDG Cost | E9: =D9*C9 -> 0
A10: 4 | B10: Travelling Cost | C10: =HYPERLINK('102025-1'!B24) -> 4000 | D10: 1 | E10: =D10*C10 -> 4000
A11: 5 | B11: Purchase | E11: =D11*C11 -> 0
A12: 6 | B12: Food | E12: =D12*C12 -> 0
A13: 7 | B13: MIS.EXP | C13: =HYPERLINK('102025-1'!B51) -> 5000 | D13: 1 | E13: =D13*C13 -> 5000
A14: 8 | B14: Over Time/Labour | C14: =HYPERLINK('102025-1'!B49) -> 7000 | D14: 1 | E14: =D14*C14 -> 7000
A15: 9 | B15: threading | E15: =D15*C15 -> 0
A16: 10 | B16: Bus Bar & Salveeve | C16: =HYPERLINK('102025-1'!E45) -> 48000 | D16: 1 | E16: =D16*C16 -> 48000
A17: 11 | B17: Cutting Disk | E17: =D17*C17 -> 0
A18: 12 | B18: Granding Disk | E18: =D18*C18 -> 0
A19: 13 | B19: Buffing Disk | E19: =D19*C19 -> 0
A20: 14 | B20: MS Rod | E20: =D20*C20 -> 0
A21: 15 | B21: MS Sheets | C21: =HYPERLINK('102025-1'!B19) -> 118196.676224 | D21: 1 | E21: =D21*C21 -> 118196.68
A22: 16 | B22: Cable | C22: =HYPERLINK('102025-1'!B47) -> 3000 | D22: 1 | E22: =D22*C22 -> 3000
A23: 17 | B23: HINGES | C23: =HYPERLINK('102025-1'!D27) -> 900 | D23: 1 | E23: =D23*C23 -> 900
A24: 18 | B24: LOCK | C24: =HYPERLINK('102025-1'!D30) -> 1100 | D24: 1 | E24: =D24*C24 -> 1100
A25: 19 | B25: ACRYLIC SHEET | C25: =HYPERLINK('102025-1'!C33) -> 500 | D25: 1 | E25: =D25*C25 -> 500
A26: 20 | B26: GAS KIT | C26: =HYPERLINK('102025-1'!C36) -> 260 | D26: 1 | E26: =D26*C26 -> 260
A27: 21 | B27: Cable Duct | C27: =HYPERLINK('102025-1'!D42) -> 1160 | D27: 1 | E27: =D27*C27 -> 1160
A28: 22 | B28: I-Bolt | C28: =HYPERLINK('102025-1'!C39) -> 440 | D28: 1 | E28: =D28*C28 -> 440
E29: =SUM(E7:E28) -> 226853.63
A32: Made By: | D32: Approved By: | I32: Director:

Sheet Sheet1

Sheet Sheet3
